<sdf version='1.6'>
  <model name='spot'>
    <static>true</static>
    <plugin name="sample" filename="libmove_object_plugin.so" />
    <link name='body'>
      <pose frame=''>0 0 0 0 -0 0</pose>
      <inertial>
        <pose frame=''>0.004614 0 0.000896 0 -0 0</pose>
        <mass>16.471</mass>
        <inertia>
          <ixx>0.104188</ixx>
          <ixy>0</ixy>
          <ixz>0.00728806</ixz>
          <iyy>1.0595</iyy>
          <iyz>0</iyz>
          <izz>1.07422</izz>
        </inertia>
      </inertial>
      <collision name='body_collision'>
        <pose frame=''>0 0 0 0 -0 0</pose>
        <geometry>
          <mesh>
            <scale>1 1 1</scale>
            <uri>model://spot_description/meshes/body_collision.stl</uri>
          </mesh>
        </geometry>
      </collision>
      <collision name='body_fixed_joint_lump__camera_link_collision_1'>
        <pose frame=''>0.38 0 -0.095 0 -0 0</pose>
        <geometry>
          <mesh>
            <scale>1 1 1</scale>
            <uri>model://hector_sensors_description/meshes/asus_camera/asus_camera_simple.dae</uri>
          </mesh>
        </geometry>
      </collision>
      <collision name='body_fixed_joint_lump__hokuyo_frame_collision_2'>
        <pose frame=''>0 0 0.1135 0 -0 0</pose>
        <geometry>
          <box>
            <size>0.058 0.058 0.087</size>
          </box>
        </geometry>
        <surface>
          <contact>
            <ode/>
          </contact>
          <friction>
            <ode/>
          </friction>
        </surface>
      </collision>
      <visual name='body_visual'>
        <pose frame=''>0 0 0 0 -0 0</pose>
        <geometry>
          <mesh>
            <scale>1 1 1</scale>
            <uri>model://spot_description/meshes/body.dae</uri>
          </mesh>
        </geometry>
      </visual>
      <visual name='body_fixed_joint_lump__camera_link_visual_1'>
        <pose frame=''>0.38 0 -0.095 0 -0 0</pose>
        <geometry>
          <mesh>
            <scale>1 1 1</scale>
            <uri>model://hector_sensors_description/meshes/asus_camera/asus_camera_simple.dae</uri>
          </mesh>
        </geometry>
      </visual>
      <visual name='body_fixed_joint_lump__hokuyo_frame_visual_2'>
        <pose frame=''>0 0 0.125 0 -0 0</pose>
        <geometry>
          <mesh>
            <scale>1 1 1</scale>
            <uri>model://hector_sensors_description/meshes/hokuyo_utm30lx/hokuyo_utm_30lx.dae</uri>
          </mesh>
        </geometry>
        <material>
          <script>
            <name>Gazebo/FlatBlack</name>
            <uri>file://media/materials/scripts/gazebo.material</uri>
          </script>
        </material>
      </visual>
      <gravity>1</gravity>
      <velocity_decay/>
    </link>
    <link name='front_left_hip'>
      <pose frame=''>0.29785 0.055 0 0 -0 0</pose>
      <inertial>
        <pose frame=''>0 0 0 0 -0 0</pose>
        <mass>2</mass>
        <inertia>
          <ixx>0.0027</ixx>
          <ixy>0</ixy>
          <ixz>0</ixz>
          <iyy>0.00416667</iyy>
          <iyz>0</iyz>
          <izz>0.00416667</izz>
        </inertia>
      </inertial>
      <collision name='front_left_hip_collision'>
        <pose frame=''>0 0 0 0 -0 0</pose>
        <geometry>
          <mesh>
            <scale>1 1 1</scale>
            <uri>model://spot_description/meshes/front_left_hip_collision.stl</uri>
          </mesh>
        </geometry>
      </collision>
      <visual name='front_left_hip_visual'>
        <pose frame=''>0 0 0 0 -0 0</pose>
        <geometry>
          <mesh>
            <scale>1 1 1</scale>
            <uri>model://spot_description/meshes/front_left_hip.dae</uri>
          </mesh>
        </geometry>
      </visual>
    </link>
    <joint name='front_left_hip_x' type='revolute'>
      <child>front_left_hip</child>
      <parent>body</parent>
      <axis>
        <xyz>1 0 0</xyz>
        <limit>
          <lower>-0.785398</lower>
          <upper>0.785398</upper>
          <effort>100</effort>
          <velocity>1000</velocity>
        </limit>
        <dynamics>
          <spring_reference>0</spring_reference>
          <spring_stiffness>0</spring_stiffness>
        </dynamics>
        <use_parent_model_frame>1</use_parent_model_frame>
      </axis>
    </joint>
    <link name='front_left_upper_leg'>
      <pose frame=''>0.29785 0.165945 0 0 -0 0</pose>
      <inertial>
        <pose frame=''>0 0 -0.14 0 -0 0</pose>
        <mass>1</mass>
        <inertia>
          <ixx>0.0155334</ixx>
          <ixy>0</ixy>
          <ixz>0</ixz>
          <iyy>0.0155334</iyy>
          <iyz>0</iyz>
          <izz>0.000962667</izz>
        </inertia>
      </inertial>
      <collision name='front_left_upper_leg_collision'>
        <pose frame=''>0 0 0 0 -0 0</pose>
        <geometry>
          <mesh>
            <scale>1 1 1</scale>
            <uri>model://spot_description/meshes/front_left_upper_leg_collision.stl</uri>
          </mesh>
        </geometry>
      </collision>
      <visual name='front_left_upper_leg_visual'>
        <pose frame=''>0 0 0 0 -0 0</pose>
        <geometry>
          <mesh>
            <scale>1 1 1</scale>
            <uri>model://spot_description/meshes/front_left_upper_leg.dae</uri>
          </mesh>
        </geometry>
      </visual>
    </link>
    <joint name='front_left_hip_y' type='revolute'>
      <child>front_left_upper_leg</child>
      <parent>front_left_hip</parent>
      <axis>
        <xyz>0 1 0</xyz>
        <limit>
          <lower>-0.898845</lower>
          <upper>2.29511</upper>
          <effort>100</effort>
          <velocity>1000</velocity>
        </limit>
        <dynamics>
          <spring_reference>0</spring_reference>
          <spring_stiffness>0</spring_stiffness>
        </dynamics>
        <use_parent_model_frame>1</use_parent_model_frame>
      </axis>
    </joint>
    <link name='front_left_lower_leg'>
      <pose frame=''>0.32285 0.165945 -0.3205 0 -0 0</pose>
      <inertial>
        <pose frame=''>0 0 -0.16 0 -0 0</pose>
        <mass>0.5</mass>
        <inertia>
          <ixx>0.00743438</ixx>
          <ixy>0</ixy>
          <ixz>0</ixz>
          <iyy>0.00740104</iyy>
          <iyz>0</iyz>
          <izz>0.000135417</izz>
        </inertia>
      </inertial>
      <collision name='front_left_lower_leg_collision'>
        <pose frame=''>0 0 0 0 -0 0</pose>
        <geometry>
          <mesh>
            <scale>0.82 0.97 0.98</scale>
            <uri>model://spot_description/meshes/front_left_lower_leg_collision.stl</uri>
          </mesh>
        </geometry>
        <surface>
          <contact>
            <ode>
              <kp>100000</kp>
              <kd>1</kd>
              <max_vel>0</max_vel>
              <min_depth>0.001</min_depth>
            </ode>
          </contact>
          <friction>
            <ode>
              <mu>0.8</mu>
              <mu2>0.8</mu2>
            </ode>
          </friction>
        </surface>
      </collision>
      <visual name='front_left_lower_leg_visual'>
        <pose frame=''>0 0 0 0 -0 0</pose>
        <geometry>
          <mesh>
            <scale>1 1 1</scale>
            <uri>model://spot_description/meshes/front_left_lower_leg.dae</uri>
          </mesh>
        </geometry>
        <material>
          <script>
            <uri>__default__</uri>
            <name>__default__</name>
          </script>
        </material>
      </visual>
      <gravity>1</gravity>
      <velocity_decay/>
    </link>
    <joint name='front_left_knee' type='revolute'>
      <child>front_left_lower_leg</child>
      <parent>front_left_upper_leg</parent>
      <axis>
        <xyz>0 1 0</xyz>
        <limit>
          <lower>-2.7929</lower>
          <upper>-0.254801</upper>
          <effort>100</effort>
          <velocity>1000</velocity>
        </limit>
        <dynamics>
          <spring_reference>0</spring_reference>
          <spring_stiffness>0</spring_stiffness>
        </dynamics>
        <use_parent_model_frame>1</use_parent_model_frame>
      </axis>
    </joint>
    <link name='front_right_hip'>
      <pose frame=''>0.29785 -0.055 0 0 -0 0</pose>
      <inertial>
        <pose frame=''>0 0 0 0 -0 0</pose>
        <mass>2</mass>
        <inertia>
          <ixx>0.0027</ixx>
          <ixy>0</ixy>
          <ixz>0</ixz>
          <iyy>0.00416667</iyy>
          <iyz>0</iyz>
          <izz>0.00416667</izz>
        </inertia>
      </inertial>
      <collision name='front_right_hip_collision'>
        <pose frame=''>0 0 0 0 -0 0</pose>
        <geometry>
          <mesh>
            <scale>1 1 1</scale>
            <uri>model://spot_description/meshes/front_right_hip_collision.stl</uri>
          </mesh>
        </geometry>
      </collision>
      <visual name='front_right_hip_visual'>
        <pose frame=''>0 0 0 0 -0 0</pose>
        <geometry>
          <mesh>
            <scale>1 1 1</scale>
            <uri>model://spot_description/meshes/front_right_hip.dae</uri>
          </mesh>
        </geometry>
      </visual>
    </link>
    <joint name='front_right_hip_x' type='revolute'>
      <child>front_right_hip</child>
      <parent>body</parent>
      <axis>
        <xyz>1 0 0</xyz>
        <limit>
          <lower>-0.785398</lower>
          <upper>0.785398</upper>
          <effort>100</effort>
          <velocity>1000</velocity>
        </limit>
        <dynamics>
          <spring_reference>0</spring_reference>
          <spring_stiffness>0</spring_stiffness>
        </dynamics>
        <use_parent_model_frame>1</use_parent_model_frame>
      </axis>
    </joint>
    <link name='front_right_upper_leg'>
      <pose frame=''>0.29785 -0.165945 0 0 -0 0</pose>
      <inertial>
        <pose frame=''>0 0 -0.14 0 -0 0</pose>
        <mass>1</mass>
        <inertia>
          <ixx>0.0155334</ixx>
          <ixy>0</ixy>
          <ixz>0</ixz>
          <iyy>0.0155334</iyy>
          <iyz>0</iyz>
          <izz>0.000962667</izz>
        </inertia>
      </inertial>
      <collision name='front_right_upper_leg_collision'>
        <pose frame=''>0 0 0 0 -0 0</pose>
        <geometry>
          <mesh>
            <scale>1 1 1</scale>
            <uri>model://spot_description/meshes/front_right_upper_leg_collision.stl</uri>
          </mesh>
        </geometry>
      </collision>
      <visual name='front_right_upper_leg_visual'>
        <pose frame=''>0 0 0 0 -0 0</pose>
        <geometry>
          <mesh>
            <scale>1 1 1</scale>
            <uri>model://spot_description/meshes/front_right_upper_leg.dae</uri>
          </mesh>
        </geometry>
      </visual>
    </link>
    <joint name='front_right_hip_y' type='revolute'>
      <child>front_right_upper_leg</child>
      <parent>front_right_hip</parent>
      <axis>
        <xyz>0 1 0</xyz>
        <limit>
          <lower>-0.898845</lower>
          <upper>2.29511</upper>
          <effort>100</effort>
          <velocity>1000</velocity>
        </limit>
        <dynamics>
          <spring_reference>0</spring_reference>
          <spring_stiffness>0</spring_stiffness>
        </dynamics>
        <use_parent_model_frame>1</use_parent_model_frame>
      </axis>
    </joint>
    <link name='front_right_lower_leg'>
      <pose frame=''>0.32285 -0.165945 -0.3205 0 -0 0</pose>
      <inertial>
        <pose frame=''>0 0 -0.16 0 -0 0</pose>
        <mass>0.5</mass>
        <inertia>
          <ixx>0.00743438</ixx>
          <ixy>0</ixy>
          <ixz>0</ixz>
          <iyy>0.00740104</iyy>
          <iyz>0</iyz>
          <izz>0.000135417</izz>
        </inertia>
      </inertial>
      <collision name='front_right_lower_leg_collision'>
        <pose frame=''>0 0 0 0 -0 0</pose>
        <geometry>
          <mesh>
            <scale>0.82 0.97 0.98</scale>
            <uri>model://spot_description/meshes/front_right_lower_leg_collision.stl</uri>
          </mesh>
        </geometry>
        <surface>
          <contact>
            <ode>
              <kp>100000</kp>
              <kd>1</kd>
              <max_vel>0</max_vel>
              <min_depth>0.001</min_depth>
            </ode>
          </contact>
          <friction>
            <ode>
              <mu>0.8</mu>
              <mu2>0.8</mu2>
            </ode>
          </friction>
        </surface>
      </collision>
      <visual name='front_right_lower_leg_visual'>
        <pose frame=''>0 0 0 0 -0 0</pose>
        <geometry>
          <mesh>
            <scale>1 1 1</scale>
            <uri>model://spot_description/meshes/front_right_lower_leg.dae</uri>
          </mesh>
        </geometry>
        <material>
          <script>
            <uri>__default__</uri>
            <name>__default__</name>
          </script>
        </material>
      </visual>
      <gravity>1</gravity>
      <velocity_decay/>
    </link>
    <joint name='front_right_knee' type='revolute'>
      <child>front_right_lower_leg</child>
      <parent>front_right_upper_leg</parent>
      <axis>
        <xyz>0 1 0</xyz>
        <limit>
          <lower>-2.7929</lower>
          <upper>-0.254801</upper>
          <effort>100</effort>
          <velocity>1000</velocity>
        </limit>
        <dynamics>
          <spring_reference>0</spring_reference>
          <spring_stiffness>0</spring_stiffness>
        </dynamics>
        <use_parent_model_frame>1</use_parent_model_frame>
      </axis>
    </joint>
    <link name='rear_left_hip'>
      <pose frame=''>-0.29785 0.055 0 0 -0 0</pose>
      <inertial>
        <pose frame=''>0 0 0 0 -0 0</pose>
        <mass>2</mass>
        <inertia>
          <ixx>0.0027</ixx>
          <ixy>0</ixy>
          <ixz>0</ixz>
          <iyy>0.00416667</iyy>
          <iyz>0</iyz>
          <izz>0.00416667</izz>
        </inertia>
      </inertial>
      <collision name='rear_left_hip_collision'>
        <pose frame=''>0 0 0 0 -0 0</pose>
        <geometry>
          <mesh>
            <scale>1 1 1</scale>
            <uri>model://spot_description/meshes/rear_left_hip_collision.stl</uri>
          </mesh>
        </geometry>
      </collision>
      <visual name='rear_left_hip_visual'>
        <pose frame=''>0 0 0 0 -0 0</pose>
        <geometry>
          <mesh>
            <scale>1 1 1</scale>
            <uri>model://spot_description/meshes/rear_left_hip.dae</uri>
          </mesh>
        </geometry>
      </visual>
    </link>
    <joint name='rear_left_hip_x' type='revolute'>
      <child>rear_left_hip</child>
      <parent>body</parent>
      <axis>
        <xyz>1 0 0</xyz>
        <limit>
          <lower>-0.785398</lower>
          <upper>0.785398</upper>
          <effort>100</effort>
          <velocity>1000</velocity>
        </limit>
        <dynamics>
          <spring_reference>0</spring_reference>
          <spring_stiffness>0</spring_stiffness>
        </dynamics>
        <use_parent_model_frame>1</use_parent_model_frame>
      </axis>
    </joint>
    <link name='rear_left_upper_leg'>
      <pose frame=''>-0.29785 0.165945 0 0 -0 0</pose>
      <inertial>
        <pose frame=''>0 0 -0.14 0 -0 0</pose>
        <mass>1</mass>
        <inertia>
          <ixx>0.0155334</ixx>
          <ixy>0</ixy>
          <ixz>0</ixz>
          <iyy>0.0155334</iyy>
          <iyz>0</iyz>
          <izz>0.000962667</izz>
        </inertia>
      </inertial>
      <collision name='rear_left_upper_leg_collision'>
        <pose frame=''>0 0 0 0 -0 0</pose>
        <geometry>
          <mesh>
            <scale>1 1 1</scale>
            <uri>model://spot_description/meshes/rear_left_upper_leg_collision.stl</uri>
          </mesh>
        </geometry>
      </collision>
      <visual name='rear_left_upper_leg_visual'>
        <pose frame=''>0 0 0 0 -0 0</pose>
        <geometry>
          <mesh>
            <scale>1 1 1</scale>
            <uri>model://spot_description/meshes/rear_left_upper_leg.dae</uri>
          </mesh>
        </geometry>
      </visual>
    </link>
    <joint name='rear_left_hip_y' type='revolute'>
      <child>rear_left_upper_leg</child>
      <parent>rear_left_hip</parent>
      <axis>
        <xyz>0 1 0</xyz>
        <limit>
          <lower>-0.898845</lower>
          <upper>2.29511</upper>
          <effort>100</effort>
          <velocity>1000</velocity>
        </limit>
        <dynamics>
          <spring_reference>0</spring_reference>
          <spring_stiffness>0</spring_stiffness>
        </dynamics>
        <use_parent_model_frame>1</use_parent_model_frame>
      </axis>
    </joint>
    <link name='rear_left_lower_leg'>
      <pose frame=''>-0.27285 0.165945 -0.3205 0 -0 0</pose>
      <inertial>
        <pose frame=''>0 0 -0.16 0 -0 0</pose>
        <mass>0.5</mass>
        <inertia>
          <ixx>0.00743438</ixx>
          <ixy>0</ixy>
          <ixz>0</ixz>
          <iyy>0.00740104</iyy>
          <iyz>0</iyz>
          <izz>0.000135417</izz>
        </inertia>
      </inertial>
      <collision name='rear_left_lower_leg_collision'>
        <pose frame=''>0 0 0 0 -0 0</pose>
        <geometry>
          <mesh>
            <scale>0.82 0.97 0.98</scale>
            <uri>model://spot_description/meshes/rear_left_lower_leg_collision.stl</uri>
          </mesh>
        </geometry>
        <surface>
          <contact>
            <ode>
              <kp>100000</kp>
              <kd>1</kd>
              <max_vel>0</max_vel>
              <min_depth>0.001</min_depth>
            </ode>
          </contact>
          <friction>
            <ode>
              <mu>0.8</mu>
              <mu2>0.8</mu2>
            </ode>
          </friction>
        </surface>
      </collision>
      <visual name='rear_left_lower_leg_visual'>
        <pose frame=''>0 0 0 0 -0 0</pose>
        <geometry>
          <mesh>
            <scale>1 1 1</scale>
            <uri>model://spot_description/meshes/rear_left_lower_leg.dae</uri>
          </mesh>
        </geometry>
        <material>
          <script>
            <uri>__default__</uri>
            <name>__default__</name>
          </script>
        </material>
      </visual>
      <gravity>1</gravity>
      <velocity_decay/>
    </link>
    <joint name='rear_left_knee' type='revolute'>
      <child>rear_left_lower_leg</child>
      <parent>rear_left_upper_leg</parent>
      <axis>
        <xyz>0 1 0</xyz>
        <limit>
          <lower>-2.7929</lower>
          <upper>-0.254801</upper>
          <effort>100</effort>
          <velocity>1000</velocity>
        </limit>
        <dynamics>
          <spring_reference>0</spring_reference>
          <spring_stiffness>0</spring_stiffness>
        </dynamics>
        <use_parent_model_frame>1</use_parent_model_frame>
      </axis>
    </joint>
    <link name='rear_right_hip'>
      <pose frame=''>-0.29785 -0.055 0 0 -0 0</pose>
      <inertial>
        <pose frame=''>0 0 0 0 -0 0</pose>
        <mass>2</mass>
        <inertia>
          <ixx>0.0027</ixx>
          <ixy>0</ixy>
          <ixz>0</ixz>
          <iyy>0.00416667</iyy>
          <iyz>0</iyz>
          <izz>0.00416667</izz>
        </inertia>
      </inertial>
      <collision name='rear_right_hip_collision'>
        <pose frame=''>0 0 0 0 -0 0</pose>
        <geometry>
          <mesh>
            <scale>1 1 1</scale>
            <uri>model://spot_description/meshes/rear_right_hip_collision.stl</uri>
          </mesh>
        </geometry>
      </collision>
      <visual name='rear_right_hip_visual'>
        <pose frame=''>0 0 0 0 -0 0</pose>
        <geometry>
          <mesh>
            <scale>1 1 1</scale>
            <uri>model://spot_description/meshes/rear_right_hip.dae</uri>
          </mesh>
        </geometry>
      </visual>
    </link>
    <joint name='rear_right_hip_x' type='revolute'>
      <child>rear_right_hip</child>
      <parent>body</parent>
      <axis>
        <xyz>1 0 0</xyz>
        <limit>
          <lower>-0.785398</lower>
          <upper>0.785398</upper>
          <effort>100</effort>
          <velocity>1000</velocity>
        </limit>
        <dynamics>
          <spring_reference>0</spring_reference>
          <spring_stiffness>0</spring_stiffness>
        </dynamics>
        <use_parent_model_frame>1</use_parent_model_frame>
      </axis>
    </joint>
    <link name='rear_right_upper_leg'>
      <pose frame=''>-0.29785 -0.165945 0 0 -0 0</pose>
      <inertial>
        <pose frame=''>0 0 -0.14 0 -0 0</pose>
        <mass>1</mass>
        <inertia>
          <ixx>0.0155334</ixx>
          <ixy>0</ixy>
          <ixz>0</ixz>
          <iyy>0.0155334</iyy>
          <iyz>0</iyz>
          <izz>0.000962667</izz>
        </inertia>
      </inertial>
      <collision name='rear_right_upper_leg_collision'>
        <pose frame=''>0 0 0 0 -0 0</pose>
        <geometry>
          <mesh>
            <scale>1 1 1</scale>
            <uri>model://spot_description/meshes/rear_right_upper_leg_collision.stl</uri>
          </mesh>
        </geometry>
      </collision>
      <visual name='rear_right_upper_leg_visual'>
        <pose frame=''>0 0 0 0 -0 0</pose>
        <geometry>
          <mesh>
            <scale>1 1 1</scale>
            <uri>model://spot_description/meshes/rear_right_upper_leg.dae</uri>
          </mesh>
        </geometry>
      </visual>
    </link>
    <joint name='rear_right_hip_y' type='revolute'>
      <child>rear_right_upper_leg</child>
      <parent>rear_right_hip</parent>
      <axis>
        <xyz>0 1 0</xyz>
        <limit>
          <lower>-0.898845</lower>
          <upper>2.29511</upper>
          <effort>100</effort>
          <velocity>1000</velocity>
        </limit>
        <dynamics>
          <spring_reference>0</spring_reference>
          <spring_stiffness>0</spring_stiffness>
        </dynamics>
        <use_parent_model_frame>1</use_parent_model_frame>
      </axis>
    </joint>
    <link name='rear_right_lower_leg'>
      <pose frame=''>-0.27285 -0.165945 -0.3205 0 -0 0</pose>
      <inertial>
        <pose frame=''>0 0 -0.16 0 -0 0</pose>
        <mass>0.5</mass>
        <inertia>
          <ixx>0.00743438</ixx>
          <ixy>0</ixy>
          <ixz>0</ixz>
          <iyy>0.00740104</iyy>
          <iyz>0</iyz>
          <izz>0.000135417</izz>
        </inertia>
      </inertial>
      <collision name='rear_right_lower_leg_collision'>
        <pose frame=''>0 0 0 0 -0 0</pose>
        <geometry>
          <mesh>
            <scale>0.82 0.97 0.98</scale>
            <uri>model://spot_description/meshes/rear_right_lower_leg_collision.stl</uri>
          </mesh>
        </geometry>
        <surface>
          <contact>
            <ode>
              <kp>100000</kp>
              <kd>1</kd>
              <max_vel>0</max_vel>
              <min_depth>0.001</min_depth>
            </ode>
          </contact>
          <friction>
            <ode>
              <mu>0.8</mu>
              <mu2>0.8</mu2>
            </ode>
          </friction>
        </surface>
      </collision>
      <visual name='rear_right_lower_leg_visual'>
        <pose frame=''>0 0 0 0 -0 0</pose>
        <geometry>
          <mesh>
            <scale>1 1 1</scale>
            <uri>model://spot_description/meshes/rear_right_lower_leg.dae</uri>
          </mesh>
        </geometry>
        <material>
          <script>
            <uri>__default__</uri>
            <name>__default__</name>
          </script>
        </material>
      </visual>
      <gravity>1</gravity>
      <velocity_decay/>
    </link>
    <joint name='rear_right_knee' type='revolute'>
      <child>rear_right_lower_leg</child>
      <parent>rear_right_upper_leg</parent>
      <axis>
        <xyz>0 1 0</xyz>
        <limit>
          <lower>-2.7929</lower>
          <upper>-0.254801</upper>
          <effort>100</effort>
          <velocity>1000</velocity>
        </limit>
        <dynamics>
          <spring_reference>0</spring_reference>
          <spring_stiffness>0</spring_stiffness>
        </dynamics>
        <use_parent_model_frame>1</use_parent_model_frame>
      </axis>
    </joint>
  </model>
</sdf>
